Workbook

Sheet Üniversiteler
A1: Üniversite | B1: Tür | C1: Şehir | D1: Bölge | E1: Büyükşehir | F1: Nüfus | G1: Geleneksel Kuruluş | H1: Sıralama | I1: Öğretim Dili | J1: Öğrenci Sayısı
A2: Abdullah Gül Üniversitesi (AGÜ) | B2: Devlet | C2: Kayseri | D2: =VLOOKUP(C2,Bölgeler!B:F,4,FALSE) -> 5 | E2: =VLOOKUP(C2,Bölgeler!B:F,2,FALSE) -> evet | F2: =VLOOKUP(C2,Bölgeler!B:F,3,FALSE) -> 1358980 | G2: 2010 | H2: 60+ | I2: karışık | J2: 2905
A3: Acıbadem Üniversitesi | B3: Vakıf | C3: İstanbul | D3: =VLOOKUP(C3,Bölgeler!B:F,4,FALSE) -> 7 | E3: =VLOOKUP(C3,Bölgeler!B:F,2,FALSE) -> evet | F3: =VLOOKUP(C3,Bölgeler!B:F,3,FALSE) -> 14804116 | G3: 2007 | H3: 60+ | I3: türkçe | J3: 5134
A4: Adana Alparslan Türkeş Bilim ve Teknoloji Üniversitesi (ATÜ) | B4: Devlet | C4: Adana | D4: =VLOOKUP(C4,Bölgeler!B:F,4,FALSE) -> 1 | E4: =VLOOKUP(C4,Bölgeler!B:F,2,FALSE) -> evet | F4: =VLOOKUP(C4,Bölgeler!B:F,3,FALSE) -> 2201670 | G4: 2011 | H4: 60+ | I4: türkçe | J4: 4192
A5: Adıyaman Üniversitesi (ADYÜ) | B5: Devlet | C5: Adıyaman | D5: =VLOOKUP(C5,Bölgeler!B:F,4,FALSE) -> 4 | E5: =VLOOKUP(C5,Bölgeler!B:F,2,FALSE) -> hayır | F5: =VLOOKUP(C5,Bölgeler!B:F,3,FALSE) -> 610484 | G5: 2006 | H5: 41-60 | I5: türkçe | J5: 18715
A6: Afyon Kocatepe Üniversitesi (AKÜ) | B6: Devlet | C6: Afyonkarahisar | D6: =VLOOKUP(C6,Bölgeler!B:F,4,FALSE) -> 3 | E6: =VLOOKUP(C6,Bölgeler!B:F,2,FALSE) -> hayır | F6: =VLOOKUP(C6,Bölgeler!B:F,3,FALSE) -> 714523 | G6: 1992 | H6: 41-60 | I6: karışık | J6: 29992
A7: Afyonkarahisar Sağlık Bilimleri Üniversitesi (AFSÜ) | B7: Devlet | C7: Afyonkarahisar | D7: =VLOOKUP(C7,Bölgeler!B:F,4,FALSE) -> 3 | E7: =VLOOKUP(C7,Bölgeler!B:F,2,FALSE) -> hayır | F7: =VLOOKUP(C7,Bölgeler!B:F,3,FALSE) -> 714523 | G7: 2018 | H7: 60+ | I7: türkçe | J7: 6736
A8: Ağrı İbrahim Çeçen Üniversitesi (AİÇÜ) | B8: Devlet | C8: Ağrı | D8: =VLOOKUP(C8,Bölgeler!B:F,4,FALSE) -> 2 | E8: =VLOOKUP(C8,Bölgeler!B:F,2,FALSE) -> hayır | F8: =VLOOKUP(C8,Bölgeler!B:F,3,FALSE) -> 542255 | G8: 2007 | H8: 60+ | I8: türkçe | J8: 13470
A9: Akdeniz Üniversitesi (AKDÜ) | B9: Devlet | C9: Antalya | D9: =VLOOKUP(C9,Bölgeler!B:F,4,FALSE) -> 1 | E9: =VLOOKUP(C9,Bölgeler!B:F,2,FALSE) -> evet | F9: =VLOOKUP(C9,Bölgeler!B:F,3,FALSE) -> 2328555 | G9: 1982 | H9: 21-40 | I9: karışık | J9: 64335
A10: Aksaray Üniversitesi (ASÜ) | B10: Devlet | C10: Aksaray | D10: =VLOOKUP(C10,Bölgeler!B:F,4,FALSE) -> 5 | E10: =VLOOKUP(C10,Bölgeler!B:F,2,FALSE) -> hayır | F10: =VLOOKUP(C10,Bölgeler!B:F,3,FALSE) -> 396673 | G10: 2006 | H10: 60+ | I10: türkçe | J10: 19224
A11: Alanya Alaaddin Keykubat Üniversitesi (ALKÜ) | B11: Devlet | C11: Antalya | D11: =VLOOKUP(C11,Bölgeler!B:F,4,FALSE) -> 1 | E11: =VLOOKUP(C11,Bölgeler!B:F,2,FALSE) -> evet | F11: =VLOOKUP(C11,Bölgeler!B:F,3,FALSE) -> 2328555 | G11: 2015 | H11: 60+ | I11: türkçe | J11: 14315
A12: Alanya Hamdullah Emin Paşa Üniversitesi | B12: Vakıf | C12: Antalya | D12: =VLOOKUP(C12,Bölgeler!B:F,4,FALSE) -> 1 | E12: =VLOOKUP(C12,Bölgeler!B:F,2,FALSE) -> evet | F12: =VLOOKUP(C12,Bölgeler!B:F,3,FALSE) -> 2328555 | G12: 2011 | H12: 60+ | I12: türkçe | J12: 423
A13: Altınbaş Üniversitesi | B13: Vakıf | C13: İstanbul | D13: =VLOOKUP(C13,Bölgeler!B:F,4,FALSE) -> 7 | E13: =VLOOKUP(C13,Bölgeler!B:F,2,FALSE) -> evet | F13: =VLOOKUP(C13,Bölgeler!B:F,3,FALSE) -> 14804116 | G13: 2008 | H13: 60+ | I13: türkçe | J13: 12451
... A15: Anadolu Üniversitesi (ANAÜ) | B15: Devlet | C15: Eskişehir | D15: =VLOOKUP(C15,Bölgeler!B:F,4,FALSE) -> 5 | E15: =VLOOKUP(C15,Bölgeler!B:F,2,FALSE) -> evet | F15: =VLOOKUP(C15,Bölgeler!B:F,3,FALSE) -> 844842 | G15: 1958 | H15: 21-40 | I15: yabancı dil | J15: 3538594
A16: Anka Teknoloji Üniversitesi | B16: Vakıf | C16: Ankara | D16: =VLOOKUP(C16,Bölgeler!B:F,4,FALSE) -> 5 | E16: =VLOOKUP(C16,Bölgeler!B:F,2,FALSE) -> evet | F16: =VLOOKUP(C16,Bölgeler!B:F,3,FALSE) -> 5346518 | G16: 2013 | H16: 60+ | I16: türkçe | J16: x
A17: Ankara Bilim Üniversitesi | B17: Vakıf | C17: Ankara | D17: =VLOOKUP(C17,Bölgeler!B:F,4,FALSE) -> 5 | E17: =VLOOKUP(C17,Bölgeler!B:F,2,FALSE) -> evet | F17: =VLOOKUP(C17,Bölgeler!B:F,3,FALSE) -> 5346518 | G17: 2020 | H17: 60+ | I17: türkçe | J17: 708
A18: Ankara Hacı Bayram Veli Üniversitesi (AHBVÜ) | B18: Devlet | C18: Ankara | D18: =VLOOKUP(C18,Bölgeler!B:F,4,FALSE) -> 5 | E18: =VLOOKUP(C18,Bölgeler!B:F,2,FALSE) -> evet | F18: =VLOOKUP(C18,Bölgeler!B:F,3,FALSE) -> 5346518 | G18: 2018 | H18: 60+ | I18: türkçe | J18: 25935
A19: Ankara Medipol Üniversitesi | B19: Vakıf | C19: Ankara | D19: =VLOOKUP(C19,Bölgeler!B:F,4,FALSE) -> 5 | E19: =VLOOKUP(C19,Bölgeler!B:F,2,FALSE) -> evet | F19: =VLOOKUP(C19,Bölgeler!B:F,3,FALSE) -> 5346518 | G19: 2018 | H19: 60+ | I19: türkçe | J19: 4626
A20: Ankara Müzik ve Güzel Sanatlar Üniversitesi (MGÜ) | B20: Devlet | C20: Ankara | D20: =VLOOKUP(C20,Bölgeler!B:F,4,FALSE) -> 5 | E20: =VLOOKUP(C20,Bölgeler!B:F,2,FALSE) -> evet | F20: =VLOOKUP(C20,Bölgeler!B:F,3,FALSE) -> 5346518 | G20: 2017 | H20: 60+ | I20: türkçe | J20: 575
A21: Ankara Sosyal Bilimler Üniversitesi (ASBÜ) | B21: Devlet | C21: Ankara | D21: =VLOOKUP(C21,Bölgeler!B:F,4,FALSE) -> 5 | E21: =VLOOKUP(C21,Bölgeler!B:F,2,FALSE) -> evet | F21: =VLOOKUP(C21,Bölgeler!B:F,3,FALSE) -> 5346518 | G21: 2013 | H21: 60+ | I21: türkçe | J21: 4079
A22: Ankara Üniversitesi (AÜ) | B22: Devlet | C22: Ankara | D22: =VLOOKUP(C22,Bölgeler!B:F,4,FALSE) -> 5 | E22: =VLOOKUP(C22,Bölgeler!B:F,2,FALSE) -> evet | F22: =VLOOKUP(C22,Bölgeler!B:F,3,FALSE) -> 5346518 | G22: 1842 | H22: 1-10 | I22: karışık | J22: 70221
A23: Ankara Yıldırım Beyazıt Üniversitesi (AYBÜ) | B23: Devlet | C23: Ankara | D23: =VLOOKUP(C23,Bölgeler!B:F,4,FALSE) -> 5 | E23: =VLOOKUP(C23,Bölgeler!B:F,2,FALSE) -> evet | F23: =VLOOKUP(C23,Bölgeler!B:F,3,FALSE) -> 5346518 | G23: 2010 | H23: 60+ | I23: türkçe | J23: 24166
A24: Antalya Akev Üniversitesi | B24: Vakıf | C24: Antalya | D24: =VLOOKUP(C24,Bölgeler!B:F,4,FALSE) -> 1 | E24: =VLOOKUP(C24,Bölgeler!B:F,2,FALSE) -> evet | F24: =VLOOKUP(C24,Bölgeler!B:F,3,FALSE) -> 2328555 | G24: 2015 | H24: 60+ | I24: türkçe | J24: 1067
A25: Antalya Bilim Üniversitesi | B25: Vakıf | C25: Antalya | D25: =VLOOKUP(C25,Bölgeler!B:F,4,FALSE) -> 1 | E25: =VLOOKUP(C25,Bölgeler!B:F,2,FALSE) -> evet | F25: =VLOOKUP(C25,Bölgeler!B:F,3,FALSE) -> 2328555 | G25: 2010 | H25: 60+ | I25: türkçe | J25: 5524
A26: Ardahan Üniversitesi (ARÜ) | B26: Devlet | C26: Ardahan | D26: =VLOOKUP(C26,Bölgeler!B:F,4,FALSE) -> 2 | E26: =VLOOKUP(C26,Bölgeler!B:F,2,FALSE) -> hayır | F26: =VLOOKUP(C26,Bölgeler!B:F,3,FALSE) -> 98335 | G26: 2008 | H26: 60+ | I26: türkçe | J26: 5546
A27: Artvin Çoruh Üniversitesi (AÇÜ) | B27: Devlet | C27: Artvin | D27: =VLOOKUP(C27,Bölgeler!B:F,4,FALSE) -> 6 | E27: =VLOOKUP(C27,Bölgeler!B:F,2,FALSE) -> hayır | F27: =VLOOKUP(C27,Bölgeler!B:F,3,FALSE) -> 168068 | G27: 2007 | H27: 41-60 | I27: türkçe | J27: 11194
A28: Atatürk Üniversitesi (ATAÜNİ) | B28: Devlet | C28: Erzurum | D28: =VLOOKUP(C28,Bölgeler!B:F,4,FALSE) -> 2 | E28: =VLOOKUP(C28,Bölgeler!B:F,2,FALSE) -> evet | F28: =VLOOKUP(C28,Bölgeler!B:F,3,FALSE) -> 762021 | G28: 1957 | H28: 11-20 | I28: türkçe | J28: 549461
... A119: İzmir Yüksek Teknoloji Enstitüsü (İYTE) | B119: Devlet | C119: İzmir | D119: =VLOOKUP(C119,Bölgeler!B:F,4,FALSE) -> 3 | E119: =VLOOKUP(C119,Bölgeler!B:F,2,FALSE) -> evet | F119: =VLOOKUP(C119,Bölgeler!B:F,3,FALSE) -> 4223545 | G119: 1992 | H119: 1-10 | I119: yabancı dil | J119: 6618
A120: Jandarma ve Sahil Güvenlik Akademisi(Askeri) | B120: Devlet | C120: Ankara | D120: =VLOOKUP(C120,Bölgeler!B:F,4,FALSE) -> 5 | E120: =VLOOKUP(C120,Bölgeler!B:F,2,FALSE) -> evet | F120: =VLOOKUP(C120,Bölgeler!B:F,3,FALSE) -> 5346518 | G120: 1904 | H120: 60+ | I120: türkçe | J120: x
A121: Kadir Has Üniversitesi | B121: Vakıf | C121: İstanbul | D121: =VLOOKUP(C121,Bölgeler!B:F,4,FALSE) -> 7 | E121: =VLOOKUP(C121,Bölgeler!B:F,2,FALSE) -> evet | F121: =VLOOKUP(C121,Bölgeler!B:F,3,FALSE) -> 14804116 | G121: 1997 | H121: 21-40 | I121: türkçe | J121: 5675
A122: Kafkas Üniversitesi (KAÜ) | B122: Devlet | C122: Kars | D122: =VLOOKUP(C122,Bölgeler!B:F,4,FALSE) -> 2 | E122: =VLOOKUP(C122,Bölgeler!B:F,2,FALSE) -> hayır | F122: =VLOOKUP(C122,Bölgeler!B:F,3,FALSE) -> 289786 | G122: 1992 | H122: 60+ | I122: türkçe | J122: 18389
A123: Kahramanmaraş İstiklal Üniversitesi (KİÜ) | B123: Devlet | C123: Kahramanmaraş | D123: =VLOOKUP(C123,Bölgeler!B:F,4,FALSE) -> 1 | E123: =VLOOKUP(C123,Bölgeler!B:F,2,FALSE) -> evet | F123: =VLOOKUP(C123,Bölgeler!B:F,3,FALSE) -> 1112634 | G123: 2018 | H123: 60+ | I123: türkçe | J123: 1446
A124: Kahramanmaraş Sütçü İmam Üniversitesi (KSÜ) | B124: Devlet | C124: Kahramanmaraş | D124: =VLOOKUP(C124,Bölgeler!B:F,4,FALSE) -> 1 | E124: =VLOOKUP(C124,Bölgeler!B:F,2,FALSE) -> evet | F124: =VLOOKUP(C124,Bölgeler!B:F,3,FALSE) -> 1112634 | G124: 1992 | H124: 60+ | I124: türkçe | J124: 32701
A125: Kapadokya Üniversitesi | B125: Vakıf | C125: Nevşehir | D125: =VLOOKUP(C125,Bölgeler!B:F,4,FALSE) -> 5 | E125: =VLOOKUP(C125,Bölgeler!B:F,2,FALSE) -> hayır | F125: =VLOOKUP(C125,Bölgeler!B:F,3,FALSE) -> 290895 | G125: 2017 | H125: 60+ | I125: türkçe | J125: 7541
A126: Karabük Üniversitesi (KBÜ) | B126: Devlet | C126: Karabük | D126: =VLOOKUP(C126,Bölgeler!B:F,4,FALSE) -> 6 | E126: =VLOOKUP(C126,Bölgeler!B:F,2,FALSE) -> hayır | F126: =VLOOKUP(C126,Bölgeler!B:F,3,FALSE) -> 242347 | G126: 2007 | H126: 60+ | I126: türkçe | J126: 45339
A127: Karadeniz Teknik Üniversitesi (KTÜ) | B127: Devlet | C127: Trabzon | D127: =VLOOKUP(C127,Bölgeler!B:F,4,FALSE) -> 6 | E127: =VLOOKUP(C127,Bölgeler!B:F,2,FALSE) -> evet | F127: =VLOOKUP(C127,Bölgeler!B:F,3,FALSE) -> 779379 | G127: 1955 | H127: 11-20 | I127: türkçe | J127: 28784
A128: Karamanoğlu Mehmetbey Üniversitesi (KMÜ) | B128: Devlet | C128: Karaman | D128: =VLOOKUP(C128,Bölgeler!B:F,4,FALSE) -> 5 | E128: =VLOOKUP(C128,Bölgeler!B:F,2,FALSE) -> hayır | F128: =VLOOKUP(C128,Bölgeler!B:F,3,FALSE) -> 245610 | G128: 2007 | H128: 60+ | I128: türkçe | J128: 18191
A129: Kastamonu Üniversitesi (KÜ) | B129: Devlet | C129: Kastamonu | D129: =VLOOKUP(C129,Bölgeler!B:F,4,FALSE) -> 6 | E129: =VLOOKUP(C129,Bölgeler!B:F,2,FALSE) -> hayır | F129: =VLOOKUP(C129,Bölgeler!B:F,3,FALSE) -> 376945 | G129: 2006 | H129: 60+ | I129: türkçe | J129: 25976
A130: Kayseri Üniversitesi (KAYÜ) | B130: Devlet | C130: Kayseri | D130: =VLOOKUP(C130,Bölgeler!B:F,4,FALSE) -> 5 | E130: =VLOOKUP(C130,Bölgeler!B:F,2,FALSE) -> evet | F130: =VLOOKUP(C130,Bölgeler!B:F,3,FALSE) -> 1358980 | G130: 2018 | H130: 60+ | I130: türkçe | J130: 11882
A131: Kırıkkale Üniversitesi (KKÜ) | B131: Devlet | C131: Kırıkkale | D131: =VLOOKUP(C131,Bölgeler!B:F,4,FALSE) -> 5 | E131: =VLOOKUP(C131,Bölgeler!B:F,2,FALSE) -> hayır | F131: =VLOOKUP(C131,Bölgeler!B:F,3,FALSE) -> 277984 | G131: 1992 | H131: 21-40 | I131: türkçe | J131: 32225
...

Sheet Sheet1
A1: Rank | B1: Institution | C1: Score
A2: 1 | B2: İstanbul Teknik Üniversitesi | C2: 86.8 | D2: 1-10
A3: 2 | B3: Orta Doğu Teknik Üniversitesi | C3: 86.6 | D3: 1-10
A4: 3 | B4: Bilkent Üniversitesi | C4: 85.8 | D4: 1-10
A5: 4 | B5: Boğaziçi Üniversitesi | C5: 85.4 | D5: 1-10
A6: 5 | B6: Sabancı Üniversitesi | C6: 83.8 | D6: 1-10
A7: 6 | B7: Koç Üniversitesi | C7: 83.5 | D7: 1-10
A8: 7 | B8: Ankara Üniversitesi | C8: 78.5 | D8: 1-10
A9: 8 | B9: Hacettepe Üniversitesi | C9: 76.5 | D9: 1-10
A10: 9 | B10: Ege Üniversitesi | C10: 75.1 | D10: 1-10
A11: 10 | B11: İzmir Institute of Technology | C11: 73.8 | D11: 1-10
A12: 11 | B12: Gebze Teknik Üniversitesi | C12: 73.4 | D12: 11-20
A13: 12 | B13: İstanbul Üniversitesi | C13: 72.8 | D13: 11-20
... A189: 190 | B189: Türkiye Uluslararası İslam, Bilim ve Teknoloji Üniversitesi | C189: 60.9 | D189: 150+

Sheet Bölgeler
A1: Id | B1: SehirAd | C1: Büyükşehir | D1: Nufus | E1: BolgeId | F1: BolgeAd
A2: 1 | B2: Adana | C2: evet | D2: 2201670 | E2: 1 | F2: Akdeniz Bölgesi
A3: 2 | B3: Adıyaman | C3: hayır | D3: 610484 | E3: 4 | F3: Güneydoğu Anadolu Bölgesi
A4: 3 | B4: Afyonkarahisar | C4: hayır | D4: 714523 | E4: 3 | F4: Ege Bölgesi
A5: 4 | B5: Ağrı | C5: hayır | D5: 542255 | E5: 2 | F5: Doğu Anadolu Bölgesi
A6: 5 | B6: Amasya | C6: hayır | D6: 326351 | E6: 6 | F6: Karadeniz Bölgesi
A7: 6 | B7: Ankara | C7: evet | D7: 5346518 | E7: 5 | F7: İç Anadolu Bölgesi
A8: 7 | B8: Antalya | C8: evet | D8: 2328555 | E8: 1 | F8: Akdeniz Bölgesi
A9: 8 | B9: Artvin | C9: hayır | D9: 168068 | E9: 6 | F9: Karadeniz Bölgesi
A10: 9 | B10: Aydın | C10: evet | D10: 1068260 | E10: 3 | F10: Ege Bölgesi
A11: 10 | B11: Balıkesir | C11: evet | D11: 1196176 | E11: 7 | F11: Marmara Bölgesi
A12: 11 | B12: Bilecik | C12: hayır | D12: 218297 | E12: 7 | F12: Marmara Bölgesi
A13: 12 | B13: Bingöl | C13: hayır | D13: 269560 | E13: 2 | F13: Doğu Anadolu Bölgesi
... A82: 81 | B82: Düzce | C82: hayır | D82: 370371 | E82: 6 | F82: Karadeniz Bölgesi
